Workbook

Sheet Erros
C1: Bitcoin | M1: S&P 500 | W1: Gold | AG1: EUR/USD | AQ1: Long Run 2020-2026
C2: Monthly | G2: Static | K2: Real world | M2: Monthly | Q2: Static | U2: Real world | W2: Monthly | AA2: Static | AE2: Real world | AG2: Monthly | AK2: Static | AO2: Real world | AQ2: Asset | AR2: Bitcoin | AV2: S&P 500 | AZ2: Gold | BD2: EUR/USD
A3: Ano previsto | C3: ARIMA | D3: XGBoost | E3: RNN | F3: RW | G3: ARIMA | H3: XGBoost | I3: RNN | J3: RW | M3: ARIMA | N3: XGBoost | O3: RNN | P3: RW | Q3: ARIMA | R3: XGBoost | S3: RNN | T3: RW | W3: ARIMA | X3: XGBoost | Y3: RNN | Z3: RW | AA3: ARIMA | AB3: XGBoost | AC3: RNN | AD3: RW | AG3: ARIMA | AH3: XGBoost | AI3: RNN | AJ3: RW | AK3: ARIMA | AL3: XGBoost | AM3: RNN | AN3: RW | AQ3: Model | AR3: ARIMA | AS3: XGBoost | AT3: RNN | AU3: RW | AV3: ARIMA | AW3: XGBoost | AX3: RNN | AY3: RW | AZ3: ARIMA | BA3: XGBoost | BB3: RNN | BC3: RW | BD3: ARIMA | BE3: XGBoost | BF3: RNN | BG3: RW
A4: 2020 | B4: 1'Abril'20 | C4: 0.41475333 | D4: 0.40075168 | E4: 0.13678391 | F4: 0.42665964 | G4: 0.46569556 | H4: 0.38329442 | I4: 0.14652557 | J4: 0.46034646 | K4: COVID crash and liquidation | M4: 0.19948593 | N4: 0.20194293 | O4: 0.19862781 | P4: 0.19947784 | Q4: 0.32068002 | R4: 0.31860757 | S4: 0.3088646 | T4: 0.32095932 | U4: COVID crash | W4: -0.0036045704 | X4: -0.0088188877 | Y4: 0.00087115712 | Z4: -0.0036108832 | AA4: -0.017928161 | AB4: -0.019929297 | AC4: -0.010662206 | AD4: -0.017928161 | AE4: COVID turns investors to gold | AG4: 0.0060207991 | AH4: 0.0072067141 | AI4: 0.0093048714 | AJ4: 0.0060207991 | AK4: 0.0237183 | AL4: 0.026637475 | AM4: 0.027732166 | AN4: 0.0237183 | AO4: COVID weakened the EUR more than the USD which was the flight-to-safety currency, and the US recovered faster than the EU, with lower rates for longer | AQ4: Real Value | AR4: 88812.1 | AV4: 6845.5 | AZ4: 4361.55 | BD4: 1.1746
B5: 1'Julho'20 | C5: 0.22329928 | D5: 0.20175083 | E5: 0.15664308 | F5: 0.21777809 | G5: 0.41518218 | H5: 0.26726075 | I5: -0.12689845 | J5: 0.41036848 | M5: -0.015992169 | N5: -0.016393337 | O5: -0.013116596 | P5: -0.016001797 | Q5: 0.057588498 | R5: 0.054064636 | S5: 0.03889085 | T5: 0.057809943 | W5: -0.013135569 | X5: -0.013798528 | Y5: -0.0085454239 | Z5: -0.013135569 | AA5: -0.10746109 | AB5: -0.10910163 | AC5: -0.094977246 | AD5: -0.10746109 | AG5: -0.0099555556 | AH5: -0.0078222222 | AI5: -0.0077333333 | AJ5: -0.0099555556 | AK5: -0.0014222222 | AL5: 0.0033777778 | AM5: 0.0055111111 | AN5: -0.0013333333 | AQ5: Forecast | AR5: 8728751.7 | AS5: 2449202.5 | AT5: 41325.33 | AU5: 8747194.8 | AV5: 4104.39 | AW5: 3934.46 | AX5: 3316.06 | AY5: 4105.26 | AZ5: 2523.25 | BA5: 2528.42 | BB5: 2959.86 | BC5: 2523.24 | BD5: 1.1509 | BE5: 1.2085 | BF5: 1.224 | BG5: 1.1511
B6: 1'Outubro'20 | C6: 0.23645591 | D6: 0.22066852 | E6: 0.041074337 | F6: 0.23548985 | G6: 0.65639942 | H6: 0.40653642 | I6: -0.187913 | J6: 0.65118309 | M6: 0.047441434 | N6: 0.046829153 | O6: 0.047793422 | P6: 0.047207761 | Q6: -0.015434217 | R6: -0.020459655 | S6: -0.041451727 | T6: -0.015227165 | W6: 0.038864195 | X6: 0.035867803 | Y6: 0.036631282 | Z6: 0.038885112 | AA6: -0.15147205 | AB6: -0.15284736 | AC6: -0.13358783 | AD6: -0.15147728 | AG6: 0.01447178 | AH6: 0.016259471 | AI6: 0.017025624 | AJ6: 0.01447178 | AK6: -0.042564059 | AL6: -0.036094322 | AM6: -0.033285094 | AN6: -0.042564059 | AQ6: Erro | AR6: =(AR5-AR4)/AR4 -> 97.283361 | AS6: =(AS5-AR4)/AR4 -> 26.577351 | AT6: =(AT5-AR4)/AR4 -> -0.53468807 | AU6: =(AU5-AR4)/AR4 -> 97.491025 | AV6: =(AV5-AV4)/AV4 -> -0.4004251 | AW6: =(AW5-AV4)/AV4 -> -0.4252487 | AX6: =(AX5-AV4)/AV4 -> -0.51558542 | AY6: =(AY5-AV4)/AV4 -> -0.40029801 | AZ6: =(AZ5-AZ4)/AZ4 -> -0.4214786 | BA6: =(BA5-AZ4)/AZ4 -> -0.42029324 | BB6: =(BB5-AZ4)/AZ4 -> -0.32137428 | BC6: =(BC5-AZ4)/AZ4 -> -0.4214809 | BD6: =(BD5-BD4)/BD4 -> -0.020177082 | BE6: =(BE5-BD4)/BD4 -> 0.028860889 | BF6: =(BF5-BD4)/BD4 -> 0.04205687 | BG6: =(BG5-BD4)/BD4 -> -0.020006811
B7: 1'Janeiro'21 | C7: -0.29695435 | D7: -0.30107562 | E7: -0.31829775 | F7: -0.29225474 | G7: -0.19303199 | H7: -0.3502076 | I7: -0.68316922 | J7: -0.19536988 | K7: Liquidity at zero rates by the FED | M7: -0.020547909 | N7: -0.021357259 | O7: -0.011038045 | P7: -0.020995181 | Q7: -0.10485876 | R7: -0.11101675 | S7: -0.13627699 | T7: -0.1046724 | U7: FED's zero rates policy and economic stimulus grows the S&P | W7: -0.033961269 | X7: -0.033787135 | Y7: -0.029328268 | Z7: -0.034014036 | AA7: -0.12544457 | AB7: -0.12678487 | AC7: -0.10211071 | AD7: -0.12544984 | AG7: -0.011053795 | AH7: -0.0095799558 | AI7: -0.012281995 | AJ7: -0.011053795 | AK7: -0.078113486 | AL7: -0.069925489 | AM7: -0.066732171 | AN7: -0.078031606
A8: 2021 | B8: 1'Abril'21 | C8: -0.063089361 | D8: -0.082914526 | E8: -0.14875601 | F8: -0.059713922 | G8: -0.33530671 | H8: -0.3718311 | I8: 0.23630316 | J8: -0.33471575 | M8: -0.025552874 | N8: -0.025769298 | O8: -0.027052912 | P8: -0.025565313 | Q8: -0.055618299 | R8: -0.056048658 | S8: -0.047438991 | T8: -0.055048633 | W8: 0.0049788688 | X8: 0.0050830776 | Y8: 0.011121403 | Z8: 0.0049788688 | AA8: 0.12215018 | AB8: 0.12383489 | AC8: 0.10136629 | AD8: 0.12215597 | AE8: FED's zero rates policy makes it easy to buy gold | AG8: 0.023779193 | AH8: 0.025392781 | AI8: 0.024458599 | AJ8: 0.023779193 | AK8: 0.03940552 | AL8: 0.042887473 | AM8: 0.046199575 | AN8: 0.039320594
B9: 1'Julho'21 | C9: 0.18461555 | D9: 0.17109613 | E9: 0.060823525 | F9: 0.20798573 | G9: 0.56969496 | H9: 0.39030098 | I9: 1.7423559 | J9: 0.57149233 | K9: China prohibits mining | M9: -0.023375541 | N9: -0.023539897 | O9: -0.022627839 | P9: -0.023387115 | Q9: -0.11125721 | R9: -0.11260214 | S9: -0.096863353 | T9: -0.11072247 | W9: 0.079496848 | X9: 0.08020036 | Y9: 0.077414453 | Z9: 0.079496848 | AA9: 0.11575304 | AB9: 0.12004728 | AC9: 0.072495498 | AD9: 0.1157643 | AG9: 0.031313302 | AH9: 0.033254558 | AI9: 0.032832546 | AJ9: 0.031397704 | AK9: 0.035111411 | AL9: 0.040850777 | AM9: 0.048446995 | AN9: 0.035111411
B10: 1'Outubro'21 | C10: 0.123204 | D10: 0.095201263 | E10: -0.0074708179 | F10: 0.12033835 | G10: 0.48021186 | H10: 0.22785278 | I10: 1.3366554 | J10: 0.48228949 | M10: 0.042898784 | N10: 0.04270599 | O10: 0.040206564 | P10: 0.042751894 | Q10: -0.10874225 | R10: -0.1110443 | S10: -0.087560248 | T10: -0.10820519 | W10: 0.039358252 | X10: 0.039847528 | Y10: 0.049138078 | Z10: 0.039403766 | AA10: 0.15387723 | AB10: 0.16106275 | AC10: 0.085566365 | AD10: 0.15388292 | AG10: 0.021562877 | AH10: 0.023632914 | AI10: 0.022511644 | AJ10: 0.021562877 | AK10: 0.060031051 | AL10: 0.068311195 | AM10: 0.08055891 | AN10: 0.059944799
B11: 1'Janeiro'22 | C11: 0.33030374 | D11: 0.29501278 | E11: 0.14150111 | F11: 0.3261517 | G11: 1.0205934 | H11: 0.56974926 | I11: 1.8798927 | J11: 1.0239526 | K11: FED raised rates 11 times, making Bitcoin more difficult to buy and FTX goes banrupt | M11: -0.04730603 | N11: -0.049152365 | O11: -0.046317821 | P11: -0.049041165 | Q11: -0.1759389 | R11: -0.17894549 | S11: -0.15008392 | T11: -0.17544165 | W11: -0.017762222 | X11: -0.016941923 | Y11: -0.019402822 | Z11: -0.017827846 | AA11: 0.13470415 | AB11: 0.14454227 | AC11: 0.04463524 | AD11: 0.13470961 | AG11: -0.0039584799 | AH11: -0.0026389866 | AI11: -0.0054539057 | AJ11: -0.0039584799 | AK11: 0.083391977 | AL11: 0.094299789 | AM11: 0.11127727 | AN11: 0.083304011
A12: 2022 | B12: 1'Abril'22 | C12: 0.054603322 | D12: 0.037879344 | E12: 0.10892758 | F12: 0.057854289 | G12: 0.31265071 | H12: 0.23391516 | I12: 0.19819124 | J12: 0.32580491 | M12: -0.048371485 | N12: -0.048985231 | O12: -0.045436947 | P12: -0.048600265 | Q12: 0.062934186 | R12: 0.061730894 | S12: 0.071119656 | T12: 0.062657011 | U12: FED increases rates 11 times, making it difficult to invest + Russia- Ukraine war | W12: 0.0039464917 | X12: 0.004310389 | Y12: 0.015324689 | Z12: 0.003772231 | AA12: -0.042888627 | AB12: -0.040833376 | AC12: -0.059735534 | AD12: -0.042786121 | AE12: The war turns investors to gold but the higher FED's rates difficult buying it | AG12: 0.0069664345 | AH12: 0.0080521125 | AI12: 0.0092282638 | AJ12: 0.0069664345 | AK12: 0.029675201 | AL12: 0.031303718 | AM12: 0.031484665 | AN12: 0.029675201 | AO12: The war in Europe crashed the EUR further, and the FED was able to raise rates before the ECB, making USD even more attractive
B13: 1'Julho'22 | C13: 0.69227323 | D13: 0.6358648 | E13: 0.66464188 | F13: 0.69255356 | G13: 3.1884192 | H13: 2.7169165 | I13: 2.623579 | J13: 3.2317309 | M13: 0.077033877 | N13: 0.0757268 | O13: 0.082481773 | P13: 0.076396023 | Q13: 0.28023726 | R13: 0.27767278 | S13: 0.30042375 | T13: 0.27990265 | W13: 0.028501079 | X13: 0.029037791 | Y13: 0.037248935 | Z13: 0.028478946 | AA13: 0.055309025 | AB13: 0.06007857 | AC13: 0.018541471 | AD13: 0.055419687 | AG13: 0.021192942 | AH13: 0.022247794 | AI13: 0.022056003 | AJ13: 0.021097046 | AK13: 0.092635213 | AL13: 0.095032605 | AM13: 0.093785961 | AN13: 0.092635213
B14: 1'Outubro'22 | C14: 0.13778137 | D14: 0.094873627 | E14: 0.058884936 | F14: 0.13531605 | G14: 4.5637685 | H14: 3.6582568 | I14: 3.5695442 | J14: 4.6231013 | M14: 0.11130572 | N14: 0.11036864 | O14: 0.11316035 | P14: 0.11049972 | Q14: 0.38450812 | R14: 0.38051997 | S14: 0.41764604 | T14: 0.38414835 | W14: 0.028498437 | X14: 0.029352008 | Y14: 0.027686944 | Z14: 0.028420293 | AA14: 0.17120101 | AB14: 0.17917769 | AC14: 0.11044121 | AD14: 0.17132123 | AG14: 0.014695377 | AH14: 0.015613838 | AI14: 0.017246658 | AJ14: 0.014797428 | AK14: 0.16409838 | AL14: 0.16746607 | AM14: 0.16420043 | AN14: 0.16420043
B15: 1'Janeiro'23 | C15: 0.10628761 | D15: 0.071624224 | E15: -0.00060294613 | F15: 0.11251203 | G15: 7.6104739 | H15: 5.8014761 | I15: 5.714298 | J15: 7.7050817 | M15: 0.063073317 | N15: 0.065792421 | O15: 0.068657377 | P15: 0.065972132 | Q15: 0.31064982 | R15: 0.3057221 | S15: 0.35326735 | T15: 0.31030863 | W15: -0.0029134721 | X15: -0.003253012 | Y15: -0.0021796276 | Z15: -0.0029353779 | AA15: 0.090054765 | AB15: 0.099989047 | AC15: 0.015109529 | AD15: 0.09016977 | AG15: -0.016725846 | AH15: -0.015884881 | AI15: -0.017006167 | AJ15: -0.016632405 | AK15: 0.067090264 | AL15: 0.070827883 | AM15: 0.066155859 | AN15: 0.067183704
A16: 2023 | B16: 1'Abril'23 | C16: -0.093443585 | D16: -0.12086582 | E16: -0.19819793 | F16: -0.094918137 | G16: -0.26199022 | H16: -0.32709015 | I16: -0.33914275 | J16: -0.26093245 | K16: Banking crisis and BTC brief safe haven | M16: -0.034533778 | N16: -0.034966941 | O16: -0.034047078 | P16: -0.034808764 | Q16: -0.055773354 | R16: -0.056586142 | S16: -0.056060507 | T16: -0.055783088 | U16: Investors got clarity that the FED was done raising rates | W16: -0.065451345 | X16: -0.065139552 | Y16: -0.066552678 | Z16: -0.065375911 | AA16: -0.062997234 | AB16: -0.062192607 | AC16: -0.079124969 | AD16: -0.063002263 | AE16: Banking crisis pushes people to save their money in assets | AG16: -0.015960882 | AH16: -0.01457699 | AI16: -0.014853769 | AJ16: -0.015960882 | AK16: -0.012178245 | AL16: -0.0085801273 | AM16: -0.010333057 | AN16: -0.012178245
B17: 1'Julho'23 | C17: -0.04325853 | D17: -0.07490813 | E17: -0.11454386 | F17: -0.047724836 | G17: -0.12711921 | H17: -0.27414506 | I17: -0.28338891 | J17: -0.12558457 | M17: -0.047386965 | N17: -0.048018371 | O17: -0.045178165 | P17: -0.047917257 | Q17: -0.11892468 | R17: -0.1204077 | S17: -0.11773826 | T17: -0.11893366 | W17: 0.043047083 | X17: 0.042869806 | Y17: 0.04868867 | Z17: 0.043083581 | AA17: -0.0087074404 | AB17: -0.0063871943 | AC17: -0.044501799 | AD17: -0.0087074404 | AG17: -0.013473877 | AH17: -0.012098992 | AI17: -0.010815765 | AJ17: -0.013565536 | AK17: -0.018148488 | AL17: -0.010815765 | AM17: -0.015582035 | AN17: -0.018148488
B18: 1'Outubro'23 | C18: 0.010079179 | D18: -0.029399274 | E18: -0.11275054 | F18: -0.00012046685 | G18: 0.2165322 | H18: -0.078322043 | I18: -0.085255143 | J18: 0.21907094 | M18: 0.057506326 | N18: 0.057294108 | O18: 0.053492846 | P18: 0.057343081 | Q18: -0.075799023 | R18: -0.078126421 | S18: -0.073028533 | T18: -0.075808351 | W18: 0.048772399 | X18: 0.047702594 | Y18: 0.057619684 | Z18: 0.04871356 | AA18: 0.03791923 | AB18: 0.041909601 | AC18: -0.019497192 | AD18: 0.037913881 | AG18: 0.019394513 | AH18: 0.020813623 | AI18: 0.02128666 | AJ18: 0.019299905 | AK18: 0.013812677 | AL18: 0.025354778 | AM18: 0.017123936 | AN18: 0.013907285 | AO18: Europe stabilized, and so did the EUR, above the USD
B19: 1'Janeiro'24 | C19: -0.047721542 | D19: -0.074907092 | E19: -0.093155574 | F19: -0.047757982 | G19: -0.018198011 | H19: -0.32229593 | I19: -0.3229206 | J19: -0.015826758 | K19: Approval of BTC ETF and stock correlation | M19: -0.033078747 | N19: -0.03268041 | O19: -0.041802328 | P19: -0.032766367 | Q19: -0.16026986 | R19: -0.16308548 | S19: -0.15633681 | T19: -0.16027825 | W19: -0.0099640029 | X19: -0.0093832493 | Y19: -0.0074202064 | Z19: -0.010035997 | AA19: -0.049493641 | AB19: -0.044406048 | AC19: -0.1199376 | AD19: -0.04949844 | AG19: -0.014487505 | AH19: -0.012495473 | AI19: -0.015574067 | AJ19: -0.014578051 | AK19: -0.02924665 | AL19: -0.014396958 | AM19: -0.025805867 | AN19: -0.029156103
A20: 2024 | B20: 1'Abril'24 | C20: -0.015430693 | D20: -0.041634752 | E20: 0.048345209 | F20: -0.024462853 | G20: -0.22911071 | H20: -0.28786712 | I20: -0.31059795 | J20: -0.22664632 | M20: -0.016364181 | N20: -0.015889332 | O20: -0.018421861 | P20: -0.015925565 | Q20: -0.078962273 | R20: -0.079206373 | S20: -0.083880491 | T20: -0.078973715 | U20: The AI boom and Magnificent 7 enormous growth | W20: -0.078614364 | X20: -0.078983926 | Y20: -0.078805824 | Z20: -0.078543123 | AA20: -0.052678214 | AB20: -0.05063449 | AC20: -0.044868427 | AD20: -0.052682666 | AE20: Gold's historical rally due to FED's rate cuts and geopolitical tensions. The war and tariffs made central banks buy gold to diversify from the weakened US dollars | AG20: 0.0089360514 | AH20: 0.010146142 | AI20: 0.012380155 | AJ20: 0.0089360514 | AK20: 0.028018244 | AL20: 0.033882528 | AM20: 0.03248627 | AN20: 0.028018244
B21: 1'Julho'24 | C21: 0.16624413 | D21: 0.13564583 | E21: 0.026476504 | F21: 0.16968585 | G21: 0.085054086 | H21: -0.075337454 | I21: -0.11950927 | J21: 0.088912722 | M21: -0.032472526 | N21: -0.031794911 | O21: -0.029964804 | P21: -0.031807696 | Q21: -0.1069334 | R21: -0.10739184 | S21: -0.11498806 | T21: -0.10694436 | W21: 0.014109197 | X21: 0.013852666 | Y21: 0.02124503 | Z21: 0.014104921 | AA21: -0.071315576 | AB21: -0.066479969 | AC21: -0.05804438 | AD21: -0.071315576 | AG21: 0.0097783572 | AH21: 0.011175265 | AI21: 0.014155336 | AJ21: 0.0097783572 | AK21: 0.029335072 | AL21: 0.040789719 | AM21: 0.037530266 | AN21: 0.029335072
B22: 1'Outubro'24 | C22: 0.018049001 | D22: -0.0088425344 | E22: -0.10883333 | F22: 0.020409465 | G22: 0.47344215 | H22: 0.12243263 | I22: 0.051773389 | J22: 0.43466151 | K22: The AI boom helps BTC. However the FED lowers rates and BTC does not explode as expected, creating uncertainty in late 2025 | M22: -0.0059382527 | N22: -0.0059697832 | O22: -0.013535362 | P22: -0.0059505146 | Q22: -0.13274535 | R22: -0.13340924 | S22: -0.14370571 | T22: -0.13275586 | W22: -0.045857756 | X22: -0.046275901 | Y22: -0.035934292 | Z22: -0.04586149 | AA22: -0.17190218 | AB22: -0.16499907 | AC22: -0.15528467 | AD22: -0.17190592 | AG22: -0.001626457 | AH22: -0.0003614349 | AI22: -0.00090358724 | AJ22: -0.0015360983 | AK22: -0.00054215234 | AL22: 0.01626457 | AM22: 0.011204482 | AN22: -0.00054215234 | AO22: The EUR/USD rallied due to FED cutting rates faster than the ECB, and geopolitical uncertainty
B23: 1'Janeiro'25 | C23: 0.1239862 | D23: 0.091525081 | E23: 0.06763448 | F23: 0.11854914 | G23: 0.17131362 | H23: -0.15206842 | I23: -0.21868884 | J23: 0.17633032 | M23: 0.030799285 | N23: 0.030732977 | O23: 0.022405354 | P23: 0.030783983 | Q23: -0.14767845 | R23: -0.14854726 | S23: -0.16149775 | T23: -0.14768865 | W23: 0.02092739 | X23: 0.020893014 | Y23: 0.026274779 | Z23: 0.020923571 | AA23: -0.13487644 | AB23: -0.12494939 | AC23: -0.1136855 | AD23: -0.13487644 | AG23: 0.021342347 | AH23: 0.022597779 | AI23: 0.020473201 | AJ23: 0.021342347 | AK23: 0.068952197 | AL23: 0.093095123 | AM23: 0.085465958 | AN23: 0.069048769
A24: 2025 | B24: 1'Abril'25 | C24: 0.084714587 | D24: 0.069399114 | E24: 0.06515355 | F24: 0.096866171 | G24: 0.38928235 | H24: 0.29462333 | I24: 0.17340044 | J24: 0.39229336 | M24: 0.060835388 | N24: 0.061873898 | O24: 0.071247117 | P24: 0.062262674 | Q24: 0.059168446 | R24: 0.057329307 | S24: 0.047806968 | T24: 0.058763694 | U24: Bubble threat and AI uncertainty | W24: -0.072015257 | X24: -0.071929434 | Y24: -0.070034965 | Z24: -0.072018436 | AA24: -0.14915448 | AB24: -0.14787349 | AC24: -0.15258423 | AD24: -0.14915766 | AG24: -0.038636153 | AH24: -0.037339016 | AI24: -0.036319837 | AJ24: -0.038728806 | AK24: -0.040581859 | AL24: -0.037246363 | AM24: -0.037061058 | AN24: -0.040674511
B25: 1'Julho'25 | C25: 0.077067448 | D25: 0.053280735 | E25: 0.025481696 | F25: 0.081379507 | G25: 0.41862314 | H25: 0.22984844 | I25: 0.019705793 | J25: 0.42182738 | M25: -0.041735977 | N25: -0.042387799 | O25: -0.044694991 | P25: -0.041748884 | Q25: -0.023877019 | R25: -0.026892503 | S25: -0.043964111 | T25: -0.024249719 | W25: 0.0066123351 | X25: 0.0042002508 | Y25: 0.0015194937 | Z25: 0.0066093498 | AA25: -0.18301988 | AB25: -0.17982268 | AC25: -0.19244134 | AD25: -0.18302287 | AG25: -0.038536461 | AH25: -0.03743542 | AI25: -0.035656814 | AJ25: -0.038536461 | AK25: -0.12297789 | AL25: -0.11671043 | AM25: -0.11781147 | AN25: -0.12297789
B26: 1'Outubro'25 | C26: -0.0061456684 | D26: -0.024197352 | E26: -0.092936272 | F26: -0.0041100153 | G26: 0.60665462 | H26: 0.29477416 | I26: -0.018813303 | J26: 0.61043203 | M26: -0.032593277 | N26: -0.033171415 | O26: -0.034852187 | P26: -0.032606687 | Q26: -0.085740255 | R26: -0.089814042 | S26: -0.11354601 | T26: -0.086090416 | W26: -0.091420141 | X26: -0.094142399 | Y26: -0.079448364 | Z26: -0.091317511 | AA26: -0.28192174 | AB26: -0.27736754 | AC26: -0.29680564 | AD26: -0.28207826 | AG26: -0.0011935209 | AH26: 8.5251492e-05 | AI26: 0.0011935209 | AJ26: -0.0011935209 | AK26: -0.11713555 | AL26: -0.10758738 | AM26: -0.11005968 | AN26: -0.11713555
B27: 1'Janeiro'26 | C27: 0.050669334 | D27: 0.024785249 | E27: -0.026899037 | F27: 0.050419819 | G27: 1.7255201 | H27: 1.0417747 | I27: 0.41345098 | J27: 1.7321798 | M27: 0.00045723468 | N27: -0.00022496531 | O27: 0.00038857644 | P27: 0.00044408736 | Q27: -0.090970711 | R27: -0.096261778 | S27: -0.12748229 | T27: -0.091319845 | W27: -0.010860818 | X27: -0.012747762 | Y27: -0.0077036833 | Z27: -0.010863111 | AA27: -0.34378604 | AB27: -0.33799452 | AC27: -0.36220839 | AD27: -0.34378833 | AG27: -0.011152733 | AH27: -0.0097054316 | AI27: -0.0080878597 | AJ27: -0.011152733 | AK27: -0.11825302 | AL27: -0.10556785 | AM27: -0.10931381 | AN27: -0.11825302
B29: AVG(ABS) | C29: {=AVERAGE(ABS(C4:C27))} -> 0.15001796 | D29: {=AVERAGE(ABS(D4:D27))} -> 0.13992101 | E29: {=AVERAGE(ABS(E4:E27))} -> 0.11770066 | F29: {=AVERAGE(ABS(F4:F27))} -> 0.15170884 | G29: {=AVERAGE(ABS(G4:G27))} -> 1.0222612 | H29: {=AVERAGE(ABS(H4:H27))} -> 0.78659072 | I29: {=AVERAGE(ABS(I4:I27))} -> 0.86674889 | J29: {=AVERAGE(ABS(J4:J27))} -> 1.0300056 | L29: AVG(ABS) | M29: {=AVERAGE(ABS(M4:M27))} -> 0.046503625 | N29: {=AVERAGE(ABS(N4:N27))} -> 0.046815343 | O29: {=AVERAGE(ABS(O4:O27))} -> 0.046939505 | P29: {=AVERAGE(ABS(P4:P27))} -> 0.046677573 | Q29: {=AVERAGE(ABS(Q4:Q27))} -> 0.13022043 | R29: {=AVERAGE(ABS(R4:R27))} -> 0.13106221 | S29: {=AVERAGE(ABS(S4:S27))} -> 0.13708012 | T29: {=AVERAGE(ABS(T4:T27))} -> 0.13011221 | V29: AVG(ABS) | W29: {=AVERAGE(ABS(W4:W27))} -> 0.033444723 | X29: {=AVERAGE(ABS(X4:X27))} -> 0.033684125 | Y29: {=AVERAGE(ABS(Y4:Y27))} -> 0.034005865 | Z29: {=AVERAGE(ABS(Z4:Z27))} -> 0.033433764 | AA29: {=AVERAGE(ABS(AA4:AA27))} -> 0.11816733 | AB29: {=AVERAGE(ABS(AB4:AB27))} -> 0.11846857 | AC29: {=AVERAGE(ABS(AC4:AC27))} -> 0.10367555 | AD29: {=AVERAGE(ABS(AD4:AD27))} -> 0.11818649 | AF29: AVG(ABS) | AG29: {=AVERAGE(ABS(AG4:AG27))} -> 0.015675635 | AH29: {=AVERAGE(ABS(AH4:AH27))} -> 0.015684044 | AI29: {=AVERAGE(ABS(AI4:AI27))} -> 0.016201674 | AJ29: {=AVERAGE(ABS(AJ4:AJ27))} -> 0.01567926 | AK29: {=AVERAGE(ABS(AK4:AK27))} -> 0.05485163 | AL29: {=AVERAGE(ABS(AL4:AL27))} -> 0.056554424 | AM29: {=AVERAGE(ABS(AM4:AM27))} -> 0.057714504 | AN29: {=AVERAGE(ABS(AN4:AN27))} -> 0.054849916
B30: STD(ABS) | C30: {=_xlfn.STDEV.P(ABS(C4:C27))} -> 0.15451145 | D30: {=_xlfn.STDEV.P(ABS(D4:D27))} -> 0.14245611 | E30: {=_xlfn.STDEV.P(ABS(E4:E27))} -> 0.13295654 | F30: {=_xlfn.STDEV.P(ABS(F4:F27))} -> 0.15486313 | G30: {=_xlfn.STDEV.P(ABS(G4:G27))} -> 1.715307 | H30: {=_xlfn.STDEV.P(ABS(H4:H27))} -> 1.3312108 | I30: {=_xlfn.STDEV.P(ABS(I4:I27))} -> 1.3526052 | J30: {=_xlfn.STDEV.P(ABS(J4:J27))} -> 1.7381535 | L30: STD(ABS) | M30: {=_xlfn.STDEV.P(ABS(M4:M27))} -> 0.039470834 | N30: {=_xlfn.STDEV.P(ABS(N4:N27))} -> 0.039816554 | O30: {=_xlfn.STDEV.P(ABS(O4:O27))} -> 0.040085536 | P30: {=_xlfn.STDEV.P(ABS(P4:P27))} -> 0.03948675 | Q30: {=_xlfn.STDEV.P(ABS(Q4:Q27))} -> 0.09595728 | R30: {=_xlfn.STDEV.P(ABS(R4:R27))} -> 0.094358248 | S30: {=_xlfn.STDEV.P(ABS(S4:S27))} -> 0.1020035 | T30: {=_xlfn.STDEV.P(ABS(T4:T27))} -> 0.095905856 | V30: STD(ABS) | W30: {=_xlfn.STDEV.P(ABS(W4:W27))} -> 0.026694598 | X30: {=_xlfn.STDEV.P(ABS(X4:X27))} -> 0.02677197 | Y30: {=_xlfn.STDEV.P(ABS(Y4:Y27))} -> 0.025755609 | Z30: {=_xlfn.STDEV.P(ABS(Z4:Z27))} -> 0.02668008 | AA30: {=_xlfn.STDEV.P(ABS(AA4:AA27))} -> 0.077683363 | AB30: {=_xlfn.STDEV.P(ABS(AB4:AB27))} -> 0.076837086 | AC30: {=_xlfn.STDEV.P(ABS(AC4:AC27))} -> 0.08307943 | AD30: {=_xlfn.STDEV.P(ABS(AD4:AD27))} -> 0.077699778 | AF30: STD(ABS) | AG30: {=_xlfn.STDEV.P(ABS(AG4:AG27))} -> 0.0098934088 | AH30: {=_xlfn.STDEV.P(ABS(AH4:AH27))} -> 0.010235239 | AI30: {=_xlfn.STDEV.P(ABS(AI4:AI27))} -> 0.0094041692 | AJ30: {=_xlfn.STDEV.P(ABS(AJ4:AJ27))} -> 0.0099075786 | AK30: {=_xlfn.STDEV.P(ABS(AK4:AK27))} -> 0.042280347 | AL30: {=_xlfn.STDEV.P(ABS(AL4:AL27))} -> 0.041232717 | AM30: {=_xlfn.STDEV.P(ABS(AM4:AM27))} -> 0.041540662 | AN30: {=_xlfn.STDEV.P(ABS(AN4:AN27))} -> 0.042292183
B31: MAX(ABS) | C31: {=MAX(ABS(C4:C27))} -> 0.69227323 | D31: {=MAX(ABS(D4:D27))} -> 0.6358648 | E31: {=MAX(ABS(E4:E27))} -> 0.66464188 | F31: {=MAX(ABS(F4:F27))} -> 0.69255356 | G31: {=MAX(ABS(G4:G27))} -> 7.6104739 | H31: {=MAX(ABS(H4:H27))} -> 5.8014761 | I31: {=MAX(ABS(I4:I27))} -> 5.714298 | J31: {=MAX(ABS(J4:J27))} -> 7.7050817 | L31: MAX(ABS) | M31: {=MAX(ABS(M4:M27))} -> 0.19948593 | N31: {=MAX(ABS(N4:N27))} -> 0.20194293 | O31: {=MAX(ABS(O4:O27))} -> 0.19862781 | P31: {=MAX(ABS(P4:P27))} -> 0.19947784 | Q31: {=MAX(ABS(Q4:Q27))} -> 0.38450812 | R31: {=MAX(ABS(R4:R27))} -> 0.38051997 | S31: {=MAX(ABS(S4:S27))} -> 0.41764604 | T31: {=MAX(ABS(T4:T27))} -> 0.38414835 | V31: MAX(ABS) | W31: {=MAX(ABS(W4:W27))} -> 0.091420141 | X31: {=MAX(ABS(X4:X27))} -> 0.094142399 | Y31: {=MAX(ABS(Y4:Y27))} -> 0.079448364 | Z31: {=MAX(ABS(Z4:Z27))} -> 0.091317511 | AA31: {=MAX(ABS(AA4:AA27))} -> 0.34378604 | AB31: {=MAX(ABS(AB4:AB27))} -> 0.33799452 | AC31: {=MAX(ABS(AC4:AC27))} -> 0.36220839 | AD31: {=MAX(ABS(AD4:AD27))} -> 0.34378833 | AF31: MAX(ABS) | AG31: {=MAX(ABS(AG4:AG27))} -> 0.038636153 | AH31: {=MAX(ABS(AH4:AH27))} -> 0.03743542 | AI31: {=MAX(ABS(AI4:AI27))} -> 0.036319837 | AJ31: {=MAX(ABS(AJ4:AJ27))} -> 0.038728806 | AK31: {=MAX(ABS(AK4:AK27))} -> 0.16409838 | AL31: {=MAX(ABS(AL4:AL27))} -> 0.16746607 | AM31: {=MAX(ABS(AM4:AM27))} -> 0.16420043 | AN31: {=MAX(ABS(AN4:AN27))} -> 0.16420043
B32: # BIGGEST | C32: {=SUMPRODUCT((ABS(C4:C27)=_xlfn.BYROW(ABS($C$4:$F$27),_xlfn.LAMBDA(_xlpm.r,LARGE(_xlpm.r,1))))*1)} -> 7 | D32: {=SUMPRODUCT((ABS(D4:D27)=_xlfn.BYROW(ABS($C$4:$F$27),_xlfn.LAMBDA(_xlpm.r,LARGE(_xlpm.r,1))))*1)} -> 0 | E32: {=SUMPRODUCT((ABS(E4:E27)=_xlfn.BYROW(ABS($C$4:$F$27),_xlfn.LAMBDA(_xlpm.r,LARGE(_xlpm.r,1))))*1)} -> 10 | F32: {=SUMPRODUCT((ABS(F4:F27)=_xlfn.BYROW(ABS($C$4:$F$27),_xlfn.LAMBDA(_xlpm.r,LARGE(_xlpm.r,1))))*1)} -> 7 | G32: {=SUMPRODUCT((ABS(G4:G27)=_xlfn.BYROW(ABS($G$4:$J$27),_xlfn.LAMBDA(_xlpm.r,LARGE(_xlpm.r,1))))*1)} -> 4 | H32: {=SUMPRODUCT((ABS(H4:H27)=_xlfn.BYROW(ABS($G$4:$J$27),_xlfn.LAMBDA(_xlpm.r,LARGE(_xlpm.r,1))))*1)} -> 1 | I32: {=SUMPRODUCT((ABS(I4:I27)=_xlfn.BYROW(ABS($G$4:$J$27),_xlfn.LAMBDA(_xlpm.r,LARGE(_xlpm.r,1))))*1)} -> 10 | J32: {=SUMPRODUCT((ABS(J4:J27)=_xlfn.BYROW(ABS($G$4:$J$27),_xlfn.LAMBDA(_xlpm.r,LARGE(_xlpm.r,1))))*1)} -> 9 | L32: # BIGGEST | M32: {=SUMPRODUCT((ABS(M4:M27)=_xlfn.BYROW(ABS($M$4:$P$27),_xlfn.LAMBDA(_xlpm.r,LARGE(_xlpm.r,1))))*1)} -> 5 | N32: {=SUMPRODUCT((ABS(N4:N27)=_xlfn.BYROW(ABS($M$4:$P$27),_xlfn.LAMBDA(_xlpm.r,LARGE(_xlpm.r,1))))*1)} -> 8 | O32: {=SUMPRODUCT((ABS(O4:O27)=_xlfn.BYROW(ABS($M$4:$P$27),_xlfn.LAMBDA(_xlpm.r,LARGE(_xlpm.r,1))))*1)} -> 11 | P32: {=SUMPRODUCT((ABS(P4:P27)=_xlfn.BYROW(ABS($M$4:$P$27),_xlfn.LAMBDA(_xlpm.r,LARGE(_xlpm.r,1))))*1)} -> 0 | Q32: {=SUMPRODUCT((ABS(Q4:Q27)=_xlfn.BYROW(ABS($Q$4:$T$27),_xlfn.LAMBDA(_xlpm.r,LARGE(_xlpm.r,1))))*1)} -> 1 | R32: {=SUMPRODUCT((ABS(R4:R27)=_xlfn.BYROW(ABS($Q$4:$T$27),_xlfn.LAMBDA(_xlpm.r,LARGE(_xlpm.r,1))))*1)} -> 8 | S32: {=SUMPRODUCT((ABS(S4:S27)=_xlfn.BYROW(ABS($Q$4:$T$27),_xlfn.LAMBDA(_xlpm.r,LARGE(_xlpm.r,1))))*1)} -> 13 | T32: {=SUMPRODUCT((ABS(T4:T27)=_xlfn.BYROW(ABS($Q$4:$T$27),_xlfn.LAMBDA(_xlpm.r,LARGE(_xlpm.r,1))))*1)} -> 2 | V32: # BIGGEST | W32: {=SUMPRODUCT((ABS(W4:W27)=_xlfn.BYROW(ABS($W$4:$Z$27),_xlfn.LAMBDA(_xlpm.r,LARGE(_xlpm.r,1))))*1)} -> 1 | X32: {=SUMPRODUCT((ABS(X4:X27)=_xlfn.BYROW(ABS($W$4:$Z$27),_xlfn.LAMBDA(_xlpm.r,LARGE(_xlpm.r,1))))*1)} -> 9 | Y32: {=SUMPRODUCT((ABS(Y4:Y27)=_xlfn.BYROW(ABS($W$4:$Z$27),_xlfn.LAMBDA(_xlpm.r,LARGE(_xlpm.r,1))))*1)} -> 10 | Z32: {=SUMPRODUCT((ABS(Z4:Z27)=_xlfn.BYROW(ABS($W$4:$Z$27),_xlfn.LAMBDA(_xlpm.r,LARGE(_xlpm.r,1))))*1)} -> 4 | AA32: {=SUMPRODUCT((ABS(AA4:AA27)=_xlfn.BYROW(ABS($AA$4:$AD$27),_xlfn.LAMBDA(_xlpm.r,LARGE(_xlpm.r,1))))*1)} -> 2 | AB32: {=SUMPRODUCT((ABS(AB4:AB27)=_xlfn.BYROW(ABS($AA$4:$AD$27),_xlfn.LAMBDA(_xlpm.r,LARGE(_xlpm.r,1))))*1)} -> 12 | AC32: {=SUMPRODUCT((ABS(AC4:AC27)=_xlfn.BYROW(ABS($AA$4:$AD$27),_xlfn.LAMBDA(_xlpm.r,LARGE(_xlpm.r,1))))*1)} -> 8 | AD32: {=SUMPRODUCT((ABS(AD4:AD27)=_xlfn.BYROW(ABS($AA$4:$AD$27),_xlfn.LAMBDA(_xlpm.r,LARGE(_xlpm.r,1))))*1)} -> 4 | AF32: # BIGGEST | AG32: {=SUMPRODUCT((ABS(AG4:AG27)=_xlfn.BYROW(ABS($AG$4:$AJ$27),_xlfn.LAMBDA(_xlpm.r,LARGE(_xlpm.r,1))))*1)} -> 6 | AH32: {=SUMPRODUCT((ABS(AH4:AH27)=_xlfn.BYROW(ABS($AG$4:$AJ$27),_xlfn.LAMBDA(_xlpm.r,LARGE(_xlpm.r,1))))*1)} -> 5 | AI32: {=SUMPRODUCT((ABS(AI4:AI27)=_xlfn.BYROW(ABS($AG$4:$AJ$27),_xlfn.LAMBDA(_xlpm.r,LARGE(_xlpm.r,1))))*1)} -> 12 | AJ32: {=SUMPRODUCT((ABS(AJ4:AJ27)=_xlfn.BYROW(ABS($AG$4:$AJ$27),_xlfn.LAMBDA(_xlpm.r,LARGE(_xlpm.r,1))))*1)} -> 7 | AK32: {=SUMPRODUCT((ABS(AK4:AK27)=_xlfn.BYROW(ABS($AK$4:$AN$27),_xlfn.LAMBDA(_xlpm.r,LARGE(_xlpm.r,1))))*1)} -> 8 | AL32: {=SUMPRODUCT((ABS(AL4:AL27)=_xlfn.BYROW(ABS($AK$4:$AN$27),_xlfn.LAMBDA(_xlpm.r,LARGE(_xlpm.r,1))))*1)} -> 8 | AM32: {=SUMPRODUCT((ABS(AM4:AM27)=_xlfn.BYROW(ABS($AK$4:$AN$27),_xlfn.LAMBDA(_xlpm.r,LARGE(_xlpm.r,1))))*1)} -> 7 | AN32: {=SUMPRODUCT((ABS(AN4:AN27)=_xlfn.BYROW(ABS($AK$4:$AN$27),_xlfn.LAMBDA(_xlpm.r,LARGE(_xlpm.r,1))))*1)} -> 7
B33: # NEGATIVE | C33: =COUNTIF(C4:C27,"<0") -> 7 | D33: =COUNTIF(D4:D27,"<0") -> 9 | E33: =COUNTIF(E4:E27,"<0") -> 11 | F33: =COUNTIF(F4:F27,"<0") -> 8 | G33: =COUNTIF(G4:G27,"<0") -> 6 | H33: =COUNTIF(H4:H27,"<0") -> 9 | I33: =COUNTIF(I4:I27,"<0") -> 11 | J33: =COUNTIF(J4:J27,"<0") -> 6 | L33: # NEGATIVE | M33: =COUNTIF(M4:M27,"<0") -> 14 | N33: =COUNTIF(N4:N27,"<0") -> 15 | O33: =COUNTIF(O4:O27,"<0") -> 14 | P33: =COUNTIF(P4:P27,"<0") -> 14 | Q33: =COUNTIF(Q4:Q27,"<0") -> 17 | R33: =COUNTIF(R4:R27,"<0") -> 17 | S33: =COUNTIF(S4:S27,"<0") -> 17 | T33: =COUNTIF(T4:T27,"<0") -> 17 | V33: # NEGATIVE | W33: =COUNTIF(W4:W27,"<0") -> 12 | X33: =COUNTIF(X4:X27,"<0") -> 12 | Y33: =COUNTIF(Y4:Y27,"<0") -> 11 | Z33: =COUNTIF(Z4:Z27,"<0") -> 12 | AA33: =COUNTIF(AA4:AA27,"<0") -> 16 | AB33: =COUNTIF(AB4:AB27,"<0") -> 16 | AC33: =COUNTIF(AC4:AC27,"<0") -> 17 | AD33: =COUNTIF(AD4:AD27,"<0") -> 16 | AF33: # NEGATIVE | AG33: =COUNTIF(AG4:AG27,"<0") -> 12 | AH33: =COUNTIF(AH4:AH27,"<0") -> 11 | AI33: =COUNTIF(AI4:AI27,"<0") -> 11 | AJ33: =COUNTIF(AJ4:AJ27,"<0") -> 12 | AK33: =COUNTIF(AK4:AK27,"<0") -> 11 | AL33: =COUNTIF(AL4:AL27,"<0") -> 9 | AM33: =COUNTIF(AM4:AM27,"<0") -> 9 | AN33: =COUNTIF(AN4:AN27,"<0") -> 11
B34: # POSITIVE | C34: =COUNTIF(C4:C27,">0") -> 17 | D34: =COUNTIF(D4:D27,">0") -> 15 | E34: =COUNTIF(E4:E27,">0") -> 13 | F34: =COUNTIF(F4:F27,">0") -> 16 | G34: =COUNTIF(G4:G27,">0") -> 18 | H34: =COUNTIF(H4:H27,">0") -> 15 | I34: =COUNTIF(I4:I27,">0") -> 13 | J34: =COUNTIF(J4:J27,">0") -> 18 | L34: # POSITIVE | M34: =COUNTIF(M4:M27,">0") -> 10 | N34: =COUNTIF(N4:N27,">0") -> 9 | O34: =COUNTIF(O4:O27,">0") -> 10 | P34: =COUNTIF(P4:P27,">0") -> 10 | Q34: =COUNTIF(Q4:Q27,">0") -> 7 | R34: =COUNTIF(R4:R27,">0") -> 7 | S34: =COUNTIF(S4:S27,">0") -> 7 | T34: =COUNTIF(T4:T27,">0") -> 7 | V34: # POSITIVE | W34: =COUNTIF(W4:W27,">0") -> 12 | X34: =COUNTIF(X4:X27,">0") -> 12 | Y34: =COUNTIF(Y4:Y27,">0") -> 13 | Z34: =COUNTIF(Z4:Z27,">0") -> 12 | AA34: =COUNTIF(AA4:AA27,">0") -> 8 | AB34: =COUNTIF(AB4:AB27,">0") -> 8 | AC34: =COUNTIF(AC4:AC27,">0") -> 7 | AD34: =COUNTIF(AD4:AD27,">0") -> 8 | AF34: # POSITIVE | AG34: =COUNTIF(AG4:AG27,">0") -> 12 | AH34: =COUNTIF(AH4:AH27,">0") -> 13 | AI34: =COUNTIF(AI4:AI27,">0") -> 13 | AJ34: =COUNTIF(AJ4:AJ27,">0") -> 12 | AK34: =COUNTIF(AK4:AK27,">0") -> 13 | AL34: =COUNTIF(AL4:AL27,">0") -> 15 | AM34: =COUNTIF(AM4:AM27,">0") -> 15 | AN34: =COUNTIF(AN4:AN27,">0") -> 13
B36: Lower than RW | C36: Yes | D36: Yes | E36: Yes | F36: - | G36: Yes | H36: Yes | I36: Yes | J36: - | L36: Lower than RW | M36: Yes | N36: No | O36: No | P36: - | Q36: No | R36: No | S36: No | T36: - | V36: Lower than RW | W36: No | X36: No | Y36: No | Z36: - | AA36: Yes | AB36: No | AC36: Yes | AD36: - | AF36: Lower than RW | AG36: Yes | AH36: No | AI36: No | AJ36: - | AK36: No | AL36: No | AM36: No | AN36: -
B37: p-value | C37: {=_xlfn.T.TEST(ABS(C4:C27),ABS(F4:F27),2,1)} -> 0.26041776 | D37: {=_xlfn.T.TEST(ABS(D4:D27),ABS(F4:F27),2,1)} -> 0.040310827 | E37: {=_xlfn.T.TEST(ABS(E4:E27),ABS(F4:F27),2,1)} -> 0.13818283 | F37: - | G37: {=_xlfn.T.TEST(ABS(G4:G27),ABS(J4:J27),2,1)} -> 0.14870564 | H37: {=_xlfn.T.TEST(ABS(H4:H27),ABS(J4:J27),2,1)} -> 0.014576982 | I37: {=_xlfn.T.TEST(ABS(I4:I27),ABS(J4:J27),2,1)} -> 0.25707774 | J37: - | L37: p-value | M37: {=_xlfn.T.TEST(ABS(M4:M27),ABS(P4:P27),2,1)} -> 0.30582491 | N37: {=_xlfn.T.TEST(ABS(N4:N27),ABS(P4:P27),2,1)} -> 0.25685829 | O37: {=_xlfn.T.TEST(ABS(O4:O27),ABS(P4:P27),2,1)} -> 0.78991535 | P37: - | Q37: {=_xlfn.T.TEST(ABS(Q4:Q27),ABS(T4:T27),2,1)} -> 0.089162289 | R37: {=_xlfn.T.TEST(ABS(R4:R27),ABS(T4:T27),2,1)} -> 0.12383914 | S37: {=_xlfn.T.TEST(ABS(S4:S27),ABS(T4:T27),2,1)} -> 0.094298181 | T37: - | V37: p-value | W37: {=_xlfn.T.TEST(ABS(W4:W27),ABS(Z4:Z27),2,1)} -> 0.35860007 | X37: {=_xlfn.T.TEST(ABS(X4:X27),ABS(Z4:Z27),2,1)} -> 0.44619773 | Y37: {=_xlfn.T.TEST(ABS(Y4:Y27),ABS(Z4:Z27),2,1)} -> 0.65406546 | Z37: - | AA37: {=_xlfn.T.TEST(ABS(AA4:AA27),ABS(AD4:AD27),2,1)} -> 0.094380076 | AB37: {=_xlfn.T.TEST(ABS(AB4:AB27),ABS(AD4:AD27),2,1)} -> 0.7973571 | AC37: {=_xlfn.T.TEST(ABS(AC4:AC27),ABS(AD4:AD27),2,1)} -> 0.0634126 | AD37: - | AF37: p-value | AG37: {=_xlfn.T.TEST(ABS(AG4:AG27),ABS(AJ4:AJ27),2,1)} -> 0.76230648 | AH37: {=_xlfn.T.TEST(ABS(AH4:AH27),ABS(AJ4:AJ27),2,1)} -> 0.9875392 | AI37: {=_xlfn.T.TEST(ABS(AI4:AI27),ABS(AJ4:AJ27),2,1)} -> 0.24193314 | AJ37: - | AK37: {=_xlfn.T.TEST(ABS(AK4:AK27),ABS(AN4:AN27),2,1)} -> 0.89503968 | AL37: {=_xlfn.T.TEST(ABS(AL4:AL27),ABS(AN4:AN27),2,1)} -> 0.38319993 | AM37: {=_xlfn.T.TEST(ABS(AM4:AM27),ABS(AN4:AN27),2,1)} -> 0.16110526 | AN37: -
B38: Win rate | C38: {=SUMPRODUCT((ABS(C4:C27)<ABS(F4:F27))*1)/24} -> 0.54166667 | D38: {=SUMPRODUCT((ABS(D4:D27)<ABS(F4:F27))*1)/24} -> 0.66666667 | E38: {=SUMPRODUCT((ABS(E4:E27)<ABS(F4:F27))*1)/24} -> 0.58333333 | F38: - | G38: {=SUMPRODUCT((ABS(G4:G27)<ABS(J4:J27))*1)/24} -> 0.625 | H38: {=SUMPRODUCT((ABS(H4:H27)<ABS(J4:J27))*1)/24} -> 0.75 | I38: {=SUMPRODUCT((ABS(I4:I27)<ABS(J4:J27))*1)/24} -> 0.58333333 | J38: - | L38: Win rate | M38: {=SUMPRODUCT((ABS(M4:M27)<ABS(P4:P27))*1)/24} -> 0.54166667 | N38: {=SUMPRODUCT((ABS(N4:N27)<ABS(P4:P27))*1)/24} -> 0.5 | O38: {=SUMPRODUCT((ABS(O4:O27)<ABS(P4:P27))*1)/24} -> 0.54166667 | P38: - | Q38: {=SUMPRODUCT((ABS(Q4:Q27)<ABS(T4:T27))*1)/24} -> 0.54166667 | R38: {=SUMPRODUCT((ABS(R4:R27)<ABS(T4:T27))*1)/24} -> 0.29166667 | S38: {=SUMPRODUCT((ABS(S4:S27)<ABS(T4:T27))*1)/24} -> 0.41666667 | T38: - | V38: Win rate | W38: {=SUMPRODUCT((ABS(W4:W27)<ABS(Z4:Z27))*1)/24} -> 0.45833333 | X38: {=SUMPRODUCT((ABS(X4:X27)<ABS(Z4:Z27))*1)/24} -> 0.45833333 | Y38: {=SUMPRODUCT((ABS(Y4:Y27)<ABS(Z4:Z27))*1)/24} -> 0.54166667 | Z38: - | AA38: {=SUMPRODUCT((ABS(AA4:AA27)<ABS(AD4:AD27))*1)/24} -> 0.70833333 | AB38: {=SUMPRODUCT((ABS(AB4:AB27)<ABS(AD4:AD27))*1)/24} -> 0.5 | AC38: {=SUMPRODUCT((ABS(AC4:AC27)<ABS(AD4:AD27))*1)/24} -> 0.66666667 | AD38: - | AF38: Win rate | AG38: {=SUMPRODUCT((ABS(AG4:AG27)<ABS(AJ4:AJ27))*1)/24} -> 0.20833333 | AH38: {=SUMPRODUCT((ABS(AH4:AH27)<ABS(AJ4:AJ27))*1)/24} -> 0.5 | AI38: {=SUMPRODUCT((ABS(AI4:AI27)<ABS(AJ4:AJ27))*1)/24} -> 0.33333333 | AJ38: - | AK38: {=SUMPRODUCT((ABS(AK4:AK27)<ABS(AN4:AN27))*1)/24} -> 0.20833333 | AL38: {=SUMPRODUCT((ABS(AL4:AL27)<ABS(AN4:AN27))*1)/24} -> 0.375 | AM38: {=SUMPRODUCT((ABS(AM4:AM27)<ABS(AN4:AN27))*1)/24} -> 0.41666667 | AN38: -
B41: Monthly | C41: Bitcoin | D41: S&P 500 | E41: Gold | F41: EUR/USD | L41: Static | M41: Bitcoin | N41: S&P 500 | O41: Gold | P41: EUR/USD | V41: Long Run | W41: Bitcoin | X41: S&P 500 | Y41: Gold | Z41: EUR/USD
B42: ARIMA | C42: 0.15 | L42: ARIMA | M42: 1.0222612 | V42: ARIMA | W42: 97.2834
B43: ARIMA | D43: 0.0465 | E43: 0.0334 | F43: 0.0157 | L43: ARIMA | N43: 0.13022043 | O43: 0.11816733 | P43: 0.05485163 | V43: ARIMA | X43: 0.4004 | Y43: 0.4215 | Z43: 0.0202
B44: Random Walk | C44: 0.15170884 | L44: Random Walk | M44: 1.0300056 | V44: Random Walk | W44: 97.491
...

Sheet RANDOM WALK
A1: Monthly Model | C1: Bitcoin | F1: S&P 500 | I1: Gold | L1: EUR/USD | O1: Static Model | Q1: Bitcoin | U1: S&P 500 | Y1: Gold | AC1: EUR/USD
A2: Ano previsto | C2: Forecast | D2: Real | E2: Erro | F2: Forecast | G2: Real | H2: Erro | I2: Forecast | J2: Real | K2: Erro | L2: Forecast | M2: Real | N2: Erro | O2: Ano previsto | Q2: Parâmetros | R2: Forecast | S2: Real | T2: Erro | U2: Parâmetros | V2: Forecast | W2: Real | X2: Erro | Y2: Parâmetros | Z2: Forecast | AA2: Real | AB2: Erro | AC2: Parâmetros | AD2: Forecast | AE2: Real | AF2: Erro | AH2: RANDOM WALK - LONG RUN 2020-2025
A3: 2020 | B3: 1'Abril'20 | C3: 9470.88 | D3: 6638.5 | E3: =(C3-D3)/D3 -> 0.42665964 | F3: 2963.31 | G3: 2470.5 | H3: =(F3-G3)/G3 -> 0.19947784 | I3: 1578.38 | J3: 1584.1 | K3: =(I3-J3)/J3 -> -0.0036108832 | L3: 1.1028 | M3: 1.0962 | N3: =(L3-M3)/M3 -> 0.0060207991 | O3: 2020 | P3: 1'Abril'20 | Q3: μ = | R3: 9694.51 | S3: 6638.5 | T3: =(R3-S3)/S3 -> 0.46034646 | U3: μ = | V3: 3263.43 | W3: 2470.5 | X3: =(V3-W3)/W3 -> 0.32095932 | Y3: μ = | Z3: 1555.7 | AA3: 1584.1 | AB3: =(Z3-AA3)/AA3 -> -0.017928161 | AC3: μ = | AD3: 1.1222 | AE3: 1.0962 | AF3: =(AD3-AE3)/AE3 -> 0.0237183 | AH3: ASSET | AI3: Bitcoin | AJ3: S&P 500 | AK3: Gold | AL3: EUR/USD
B4: 1'Julho'20 | C4: 11239.97 | D4: 9229.9 | E4: =(C4-D4)/D4 -> 0.21777809 | F4: 3066.04 | G4: 3115.9 | H4: =(F4-G4)/G4 -> -0.016001797 | I4: 1756.52 | J4: 1779.9 | K4: =(I4-J4)/J4 -> -0.013135569 | L4: 1.1138 | M4: 1.125 | N4: =(L4-M4)/M4 -> -0.0099555556 | P4: 1'Julho'20 | Q4: 0.003239 | R4: 13017.56 | S4: 9229.9 | T4: =(R4-S4)/S4 -> 0.41036848 | U4: 0.000109 | V4: 3296.03 | W4: 3115.9 | X4: =(V4-W4)/W4 -> 0.057809943 | Y4: 0.00023 | Z4: 1588.63 | AA4: 1779.9 | AB4: =(Z4-AA4)/AA4 -> -0.10746109 | AC4: 1.2e-05 | AD4: 1.1235 | AE4: 1.125 | AF4: =(AD4-AE4)/AE4 -> -0.0013333333 | AH4: Jan 1st, 2026 | AI4: 88812.1 | AJ4: 6845.5 | AK4: 4361.55 | AL4: 1.1746
B5: 1'Outubro'20 | C5: 13121.52 | D5: 10620.5 | E5: =(C5-D5)/D5 -> 0.23548985 | F5: 3540.4 | G5: 3380.8 | H5: =(F5-G5)/G5 -> 0.047207761 | I5: 1986.66 | J5: 1912.3 | K5: =(I5-J5)/J5 -> 0.038885112 | L5: 1.1917 | M5: 1.1747 | N5: =(L5-M5)/M5 -> 0.01447178 | P5: 1'Outubro'20 | Q5: σ = | R5: 17536.39 | S5: 10620.5 | T5: =(R5-S5)/S5 -> 0.65118309 | U5: σ = | V5: 3329.32 | W5: 3380.8 | X5: =(V5-W5)/W5 -> -0.015227165 | Y5: σ = | Z5: 1622.63 | AA5: 1912.3 | AB5: =(Z5-AA5)/AA5 -> -0.15147728 | AC5: σ = | AD5: 1.1247 | AE5: 1.1747 | AF5: =(AD5-AE5)/AE5 -> -0.042564059 | AH5: Forecast | AI5: 8747194.8 | AJ5: 4105.26 | AK5: 2523.24 | AL5: 1.1511
B6: 1'Janeiro'21 | C6: 20779.33 | D6: 29359.9 | E6: =(C6-D6)/D6 -> -0.29225474 | F6: 3677.24 | G6: 3756.1 | H6: =(F6-G6)/G6 -> -0.020995181 | I6: 1830.64 | J6: 1895.1 | K6: =(I6-J6)/J6 -> -0.034014036 | L6: 1.2078 | M6: 1.2213 | N6: =(L6-M6)/M6 -> -0.011053795 | P6: 1'Janeiro'21 | Q6: 0.06963 | R6: 23623.86 | S6: 29359.9 | T6: =(R6-S6)/S6 -> -0.19536988 | U6: 0.009875 | V6: 3362.94 | W6: 3756.1 | X6: =(V6-W6)/W6 -> -0.1046724 | Y6: 0.009122 | Z6: 1657.36 | AA6: 1895.1 | AB6: =(Z6-AA6)/AA6 -> -0.12544984 | AC6: 0.005149 | AD6: 1.126 | AE6: 1.2213 | AF6: =(AD6-AE6)/AE6 -> -0.078031606 | AH6: Erro | AI6: =(AI5-AI4)/AI4 -> 97.491025 | AJ6: =(AJ5-AJ4)/AJ4 -> -0.40029801 | AK6: =(AK5-AK4)/AK4 -> -0.4214809 | AL6: =(AL5-AL4)/AL4 -> -0.020006811
A7: 2021 | B7: 1'Abril'21 | C7: 55212 | D7: 58718.3 | E7: =(C7-D7)/D7 -> -0.059713922 | F7: 3917.13 | G7: 4019.9 | H7: =(F7-G7)/G7 -> -0.025565313 | I7: 1735.9 | J7: 1727.3 | K7: =(I7-J7)/J7 -> 0.0049788688 | L7: 1.2055 | M7: 1.1775 | N7: =(L7-M7)/M7 -> 0.023779193 | O7: 2021 | P7: 1'Abril'21 | Q7: μ = | R7: 39064.36 | S7: 58718.3 | T7: =(R7-S7)/S7 -> -0.33471575 | U7: μ = | V7: 3798.61 | W7: 4019.9 | X7: =(V7-W7)/W7 -> -0.055048633 | Y7: μ = | Z7: 1938.3 | AA7: 1727.3 | AB7: =(Z7-AA7)/AA7 -> 0.12215597 | AC7: μ = | AD7: 1.2238 | AE7: 1.1775 | AF7: =(AD7-AE7)/AE7 -> 0.039320594 | AH7: μ (daily drift) | AI7: 0.003239 | AJ7: 0.000109 | AK7: 0.00023 | AL7: 1.2e-05
B8: 1'Julho'21 | C8: 40520.19 | D8: 33543.6 | E8: =(C8-D8)/D8 -> 0.20798573 | F8: 4218.87 | G8: 4319.9 | H8: =(F8-G8)/G8 -> -0.023387115 | I8: 1918.05 | J8: 1776.8 | K8: =(I8-J8)/J8 -> 0.079496848 | L8: 1.222 | M8: 1.1848 | N8: =(L8-M8)/M8 -> 0.031397704 | P8: 1'Julho'21 | Q8: 0.003293 | R8: 52713.51 | S8: 33543.6 | T8: =(R8-S8)/S8 -> 0.57149233 | U8: 0.000124 | V8: 3841.59 | W8: 4319.9 | X8: =(V8-W8)/W8 -> -0.11072247 | Y8: 0.000248 | Z8: 1982.49 | AA8: 1776.8 | AB8: =(Z8-AA8)/AA8 -> 0.1157643 | AC8: 2.3e-05 | AD8: 1.2264 | AE8: 1.1848 | AF8: =(AD8-AE8)/AE8 -> 0.035111411 | AH8: σ (daily volatility) | AI8: 0.06963 | AJ8: 0.009875 | AK8: 0.009122 | AL8: 0.005149
B9: 1'Outubro'21 | C9: 53939.81 | D9: 48146 | E9: =(C9-D9)/D9 -> 0.12033835 | F9: 4543.27 | G9: 4357 | H9: =(F9-G9)/G9 -> 0.042751894 | I9: 1826.96 | J9: 1757.7 | K9: =(I9-J9)/J9 -> 0.039403766 | L9: 1.1844 | M9: 1.1594 | N9: =(L9-M9)/M9 -> 0.021562877 | P9: 1'Outubro'21 | Q9: σ = | R9: 71366.31 | S9: 48146 | T9: =(R9-S9)/S9 -> 0.48228949 | U9: σ = | V9: 3885.55 | W9: 4357 | X9: =(V9-W9)/W9 -> -0.10820519 | Y9: σ = | Z9: 2028.18 | AA9: 1757.7 | AB9: =(Z9-AA9)/AA9 -> 0.15388292 | AC9: σ = | AD9: 1.2289 | AE9: 1.1594 | AF9: =(AD9-AE9)/AE9 -> 0.059944799 | AH9: σ^2 | AI9: =AI8*AI8 -> 0.0048483369 | AJ9: =AJ8*AJ8 -> 9.7515625e-05 | AK9: =AK8*AK8 -> 8.3210884e-05 | AL9: =AL8*AL8 -> 2.6512201e-05
B10: 1'Janeiro'22 | C10: 63307.83 | D10: 47738 | E10: =(C10-D10)/D10 -> 0.3261517 | F10: 4532.46 | G10: 4766.2 | H10: =(F10-G10)/G10 -> -0.049041165 | I10: 1796 | J10: 1828.6 | K10: =(I10-J10)/J10 -> -0.017827846 | L10: 1.1323 | M10: 1.1368 | N10: =(L10-M10)/M10 -> -0.0039584799 | P10: 1'Janeiro'22 | Q10: 0.067471 | R10: 96619.45 | S10: 47738 | T10: =(R10-S10)/S10 -> 1.0239526 | U10: 0.010419 | V10: 3930.01 | W10: 4766.2 | X10: =(V10-W10)/W10 -> -0.17544165 | Y10: 0.009236 | Z10: 2074.93 | AA10: 1828.6 | AB10: =(Z10-AA10)/AA10 -> 0.13470961 | AC10: 0.005098 | AD10: 1.2315 | AE10: 1.1368 | AF10: =(AD10-AE10)/AE10 -> 0.083304011 | AH10: Sigma2 (ARIMA) | AI10: 0.004637 | AJ10: 9.7e-05 | AK10: 8.3e-05 | AL10: 2.6e-05
A11: 2022 | B11: 1'Abril'22 | C11: 48975.48 | D11: 46297 | E11: =(C11-D11)/D11 -> 0.057854289 | F11: 4324.93 | G11: 4545.86 | H11: =(F11-G11)/G11 -> -0.048600265 | I11: 1958.46 | J11: 1951.1 | K11: =(I11-J11)/J11 -> 0.003772231 | L11: 1.113 | M11: 1.1053 | N11: =(L11-M11)/M11 -> 0.0069664345 | O11: 2022 | P11: 1'Abril'22 | Q11: μ = | R11: 61380.79 | S11: 46297 | T11: =(R11-S11)/S11 -> 0.32580491 | U11: μ = | V11: 4830.69 | W11: 4545.86 | X11: =(V11-W11)/W11 -> 0.062657011 | Y11: μ = | Z11: 1867.62 | AA11: 1951.1 | AB11: =(Z11-AA11)/AA11 -> -0.042786121 | AC11: μ = | AD11: 1.1381 | AE11: 1.1053 | AF11: =(AD11-AE11)/AE11 -> 0.029675201
B12: 1'Julho'22 | C12: 32603.49 | D12: 19262.9 | E12: =(C12-D12)/D12 -> 0.69255356 | F12: 4117.57 | G12: 3825.33 | H12: =(F12-G12)/G12 -> 0.076396023 | I12: 1858.77 | J12: 1807.3 | K12: =(I12-J12)/J12 -> 0.028478946 | L12: 1.0648 | M12: 1.0428 | N12: =(L12-M12)/M12 -> 0.021097046 | P12: 1'Julho'22 | Q12: 0.003118 | R12: 81515.41 | S12: 19262.9 | T12: =(R12-S12)/S12 -> 3.2317309 | U12: 0.000148 | V12: 4896.05 | W12: 3825.33 | X12: =(V12-W12)/W12 -> 0.27990265 | Y12: 0.000232 | Z12: 1907.46 | AA12: 1807.3 | AB12: =(Z12-AA12)/AA12 -> 0.055419687 | AC12: 1.3e-05 | AD12: 1.1394 | AE12: 1.0428 | AF12: =(AD12-AE12)/AE12 -> 0.092635213
B13: 1'Outubro'22 | C13: 21925.11 | D13: 19311.9 | E13: =(C13-D13)/D13 -> 0.13531605 | F13: 3981.83 | G13: 3585.62 | H13: =(F13-G13)/G13 -> 0.11049972 | I13: 1710.88 | J13: 1663.6 | K13: =(I13-J13)/J13 -> 0.028420293 | L13: 0.9944 | M13: 0.9799 | N13: =(L13-M13)/M13 -> 0.014797428 | P13: 1'Outubro'22 | Q13: σ = | R13: 108592.77 | S13: 19311.9 | T13: =(R13-S13)/S13 -> 4.6231013 | U13: σ = | V13: 4963.03 | W13: 3585.62 | X13: =(V13-W13)/W13 -> 0.38414835 | Y13: σ = | Z13: 1948.61 | AA13: 1663.6 | AB13: =(Z13-AA13)/AA13 -> 0.17132123 | AC13: σ = | AD13: 1.1408 | AE13: 0.9799 | AF13: =(AD13-AE13)/AE13 -> 0.16420043
B14: 1'Janeiro'23 | C14: 18488.17 | D14: 16618.4 | E14: =(C14-D14)/D14 -> 0.11251203 | F14: 4092.8 | G14: 3839.5 | H14: =(F14-G14)/G14 -> 0.065972132 | I14: 1820.64 | J14: 1826 | K14: =(I14-J14)/J14 -> -0.0029353779 | L14: 1.0524 | M14: 1.0702 | N14: =(L14-M14)/M14 -> -0.016632405 | P14: 1'Janeiro'23 | Q14: 0.065661 | R14: 144664.53 | S14: 16618.4 | T14: =(R14-S14)/S14 -> 7.7050817 | U14: 0.010285 | V14: 5030.93 | W14: 3839.5 | X14: =(V14-W14)/W14 -> 0.31030863 | Y14: 0.009177 | Z14: 1990.65 | AA14: 1826 | AB14: =(Z14-AA14)/AA14 -> 0.09016977 | AC14: 0.005022 | AD14: 1.1421 | AE14: 1.0702 | AF14: =(AD14-AE14)/AE14 -> 0.067183704
A15: 2023 | B15: 1'Abril'23 | C15: 25755.1 | D15: 28456.1 | E15: =(C15-D15)/D15 -> -0.094918137 | F15: 3966.27 | G15: 4109.31 | H15: =(F15-G15)/G15 -> -0.034808764 | I15: 1858.5 | J15: 1988.5 | K15: =(I15-J15)/J15 -> -0.065375911 | L15: 1.0666 | M15: 1.0839 | N15: =(L15-M15)/M15 -> -0.015960882 | O15: 2023 | P15: 1'Abril'23 | Q15: μ = | R15: 21030.98 | S15: 28456.1 | T15: =(R15-S15)/S15 -> -0.26093245 | U15: μ = | V15: 3880.08 | W15: 4109.31 | X15: =(V15-W15)/W15 -> -0.055783088 | Y15: μ = | Z15: 1863.22 | AA15: 1988.5 | AB15: =(Z15-AA15)/AA15 -> -0.063002263 | AC15: μ = | AD15: 1.0707 | AE15: 1.0839 | AF15: =(AD15-AE15)/AE15 -> -0.012178245
B16: 1'Julho'23 | C16: 29127.05 | D16: 30586.8 | E16: =(C16-D16)/D16 -> -0.047724836 | F16: 4237.13 | G16: 4450.38 | H16: =(F16-G16)/G16 -> -0.047917257 | I16: 2000.53 | J16: 1917.9 | K16: =(I16-J16)/J16 -> 0.043083581 | L16: 1.0762 | M16: 1.091 | N16: =(L16-M16)/M16 -> -0.013565536 | P16: 1'Julho'23 | Q16: 0.002641 | R16: 26745.57 | S16: 30586.8 | T16: =(R16-S16)/S16 -> -0.12558457 | U16: 0.000116 | V16: 3921.08 | W16: 4450.38 | X16: =(V16-W16)/W16 -> -0.11893366 | Y16: 0.000222 | Z16: 1901.2 | AA16: 1917.9 | AB16: =(Z16-AA16)/AA16 -> -0.0087074404 | AC16: 5e-06 | AD16: 1.0712 | AE16: 1.091 | AF16: =(AD16-AE16)/AE16 -> -0.018148488
B17: 1'Outubro'23 | C17: 27971.13 | D17: 27974.5 | E17: =(C17-D17)/D17 -> -0.00012046685 | F17: 4533.94 | G17: 4288.05 | H17: =(F17-G17)/G17 -> 0.057343081 | I17: 1960.57 | J17: 1869.5 | K17: =(I17-J17)/J17 -> 0.04871356 | L17: 1.0774 | M17: 1.057 | N17: =(L17-M17)/M17 -> 0.019299905 | P17: 1'Outubro'23 | Q17: σ = | R17: 34102.9 | S17: 27974.5 | T17: =(R17-S17)/S17 -> 0.21907094 | U17: σ = | V17: 3962.98 | W17: 4288.05 | X17: =(V17-W17)/W17 -> -0.075808351 | Y17: σ = | Z17: 1940.38 | AA17: 1869.5 | AB17: =(Z17-AA17)/AA17 -> 0.037913881 | AC17: σ = | AD17: 1.0717 | AE17: 1.057 | AF17: =(AD17-AE17)/AE17 -> 0.013907285
B18: 1'Janeiro'24 | C18: 42073.29 | D18: 44183.4 | E18: =(C18-D18)/D18 -> -0.047757982 | F18: 4613.54 | G18: 4769.83 | H18: =(F18-G18)/G18 -> -0.032766367 | I18: 2062.59 | J18: 2083.5 | K18: =(I18-J18)/J18 -> -0.010035997 | L18: 1.0883 | M18: 1.1044 | N18: =(L18-M18)/M18 -> -0.014578051 | P18: 1'Janeiro'24 | Q18: 0.063716 | R18: 43484.12 | S18: 44183.4 | T18: =(R18-S18)/S18 -> -0.015826758 | U18: 0.010398 | V18: 4005.33 | W18: 4769.83 | X18: =(V18-W18)/W18 -> -0.16027825 | Y18: 0.009133 | Z18: 1980.37 | AA18: 2083.5 | AB18: =(Z18-AA18)/AA18 -> -0.04949844 | AC18: 0.005033 | AD18: 1.0722 | AE18: 1.1044 | AF18: =(AD18-AE18)/AE18 -> -0.029156103
A19: 2024 | B19: 1'Abril'24 | C19: 67960.21 | D19: 69664.4 | E19: =(C19-D19)/D19 -> -0.024462853 | F19: 5160.26 | G19: 5243.77 | H19: =(F19-G19)/G19 -> -0.015925565 | I19: 2069.5 | J19: 2245.9 | K19: =(I19-J19)/J19 -> -0.078543123 | L19: 1.0839 | M19: 1.0743 | N19: =(L19-M19)/M19 -> 0.0089360514 | O19: 2024 | P19: 1'Abril'24 | Q19: μ = | R19: 53875.22 | S19: 69664.4 | T19: =(R19-S19)/S19 -> -0.22664632 | U19: μ = | V19: 4829.65 | W19: 5243.77 | X19: =(V19-W19)/W19 -> -0.078973715 | Y19: μ = | Z19: 2127.58 | AA19: 2245.9 | AB19: =(Z19-AA19)/AA19 -> -0.052682666 | AC19: μ = | AD19: 1.1044 | AE19: 1.0743 | AF19: =(AD19-AE19)/AE19 -> 0.028018244
B20: 1'Julho'24 | C20: 73561.66 | D20: 62890.1 | E20: =(C20-D20)/D20 -> 0.16968585 | F20: 5300.94 | G20: 5475.09 | H20: =(F20-G20)/G20 -> -0.031807696 | I20: 2371.89 | J20: 2338.9 | K20: =(I20-J20)/J20 -> 0.014104921 | L20: 1.0843 | M20: 1.0738 | N20: =(L20-M20)/M20 -> 0.0097783572 | P20: 1'Julho'24 | Q20: 0.002636 | R20: 68481.83 | S20: 62890.1 | T20: =(R20-S20)/S20 -> 0.088912722 | U20: 0.000135 | V20: 4889.56 | W20: 5475.09 | X20: =(V20-W20)/W20 -> -0.10694436 | Y20: 0.000228 | Z20: 2172.1 | AA20: 2338.9 | AB20: =(Z20-AA20)/AA20 -> -0.071315576 | AC20: 8e-06 | AD20: 1.1053 | AE20: 1.0738 | AF20: =(AD20-AE20)/AE20 -> 0.029335072
B21: 1'Outubro'24 | C21: 62077.12 | D21: 60835.5 | E21: =(C21-D21)/D21 -> 0.020409465 | F21: 5674.78 | G21: 5708.75 | H21: =(F21-G21)/G21 -> -0.0059505146 | I21: 2555.66 | J21: 2678.5 | K21: =(I21-J21)/J21 -> -0.04586149 | L21: 1.105 | M21: 1.1067 | N21: =(L21-M21)/M21 -> -0.0015360983 | P21: 1'Outubro'24 | Q21: σ = | R21: 87278.35 | S21: 60835.5 | T21: =(R21-S21)/S21 -> 0.43466151 | U21: σ = | V21: 4950.88 | W21: 5708.75 | X21: =(V21-W21)/W21 -> -0.13275586 | Y21: σ = | Z21: 2218.05 | AA21: 2678.5 | AB21: =(Z21-AA21)/AA21 -> -0.17190592 | AC21: σ = | AD21: 1.1061 | AE21: 1.1067 | AF21: =(AD21-AE21)/AE21 -> -0.00054215234
B22: 1'Janeiro'25 | C22: 105770.23 | D22: 94560.2 | E22: =(C22-D22)/D22 -> 0.11854914 | F22: 6062.69 | G22: 5881.63 | H22: =(F22-G22)/G22 -> 0.030783983 | I22: 2672.88 | J22: 2618.1 | K22: =(I22-J22)/J22 -> 0.020923571 | L22: 1.0576 | M22: 1.0355 | N22: =(L22-M22)/M22 -> 0.021342347 | P22: 1'Janeiro'25 | Q22: 0.061616 | R22: 111234.03 | S22: 94560.2 | T22: =(R22-S22)/S22 -> 0.17633032 | U22: 0.010275 | V22: 5012.98 | W22: 5881.63 | X22: =(V22-W22)/W22 -> -0.14768865 | Y22: 0.009057 | Z22: 2264.98 | AA22: 2618.1 | AB22: =(Z22-AA22)/AA22 -> -0.13487644 | AC22: 0.004992 | AD22: 1.107 | AE22: 1.0355 | AF22: =(AD22-AE22)/AE22 -> 0.069048769
A23: 2025 | B23: 1'Abril'25 | C23: 93413.73 | D23: 85164.2 | E23: =(C23-D23)/D23 -> 0.096866171 | F23: 5983.8 | G23: 5633.07 | H23: =(F23-G23)/G23 -> 0.062262674 | I23: 2919.43 | J23: 3146 | K23: =(I23-J23)/J23 -> -0.072018436 | L23: 1.0375 | M23: 1.0793 | N23: =(L23-M23)/M23 -> -0.038728806 | O23: 2025 | P23: 1'Abril'25 | Q23: μ = | R23: 118573.55 | S23: 85164.2 | T23: =(R23-S23)/S23 -> 0.39229336 | U23: μ = | V23: 5964.09 | W23: 5633.07 | X23: =(V23-W23)/W23 -> 0.058763694 | Y23: μ = | Z23: 2676.75 | AA23: 3146 | AB23: =(Z23-AA23)/AA23 -> -0.14915766 | AC23: μ = | AD23: 1.0354 | AE23: 1.0793 | AF23: =(AD23-AE23)/AE23 -> -0.040674511
B24: 1'Julho'25 | C24: 114295.65 | D24: 105694.3 | E24: =(C24-D24)/D24 -> 0.081379507 | F24: 5939.25 | G24: 6198.01 | H24: =(F24-G24)/G24 -> -0.041748884 | I24: 3371.94 | J24: 3349.8 | K24: =(I24-J24)/J24 -> 0.0066093498 | L24: 1.1352 | M24: 1.1807 | N24: =(L24-M24)/M24 -> -0.038536461 | P24: 1'Julho'25 | Q24: 0.002604 | R24: 150279.05 | S24: 105694.3 | T24: =(R24-S24)/S24 -> 0.42182738 | U24: 0.000153 | V24: 6047.71 | W24: 6198.01 | X24: =(V24-W24)/W24 -> -0.024249719 | Y24: 0.000243 | Z24: 2736.71 | AA24: 3349.8 | AB24: =(Z24-AA24)/AA24 -> -0.18302287 | AC24: 1e-06 | AD24: 1.0355 | AE24: 1.1807 | AF24: =(AD24-AE24)/AE24 -> -0.12297789
B25: 1'Outubro'25 | C25: 118088.85 | D25: 118576.2 | E25: =(C25-D25)/D25 -> -0.0041100153 | F25: 6492.37 | G25: 6711.2 | H25: =(F25-G25)/G25 -> -0.032606687 | I25: 3541.59 | J25: 3897.5 | K25: =(I25-J25)/J25 -> -0.091317511 | L25: 1.1716 | M25: 1.173 | N25: =(L25-M25)/M25 -> -0.0011935209 | P25: 1'Outubro'25 | Q25: σ = | R25: 190958.91 | S25: 118576.2 | T25: =(R25-S25)/S25 -> 0.61043203 | U25: σ = | V25: 6133.43 | W25: 6711.2 | X25: =(V25-W25)/W25 -> -0.086090416 | Y25: σ = | Z25: 2798.1 | AA25: 3897.5 | AB25: =(Z25-AA25)/AA25 -> -0.28207826 | AC25: σ = | AD25: 1.0356 | AE25: 1.173 | AF25: =(AD25-AE25)/AE25 -> -0.11713555
B26: 1'Janeiro'26 | C26: 93289.99 | D26: 88812.1 | E26: =(C26-D26)/D26 -> 0.050419819 | F26: 6848.54 | G26: 6845.5 | H26: =(F26-G26)/G26 -> 0.00044408736 | I26: 4314.17 | J26: 4361.55 | K26: =(I26-J26)/J26 -> -0.010863111 | L26: 1.1615 | M26: 1.1746 | N26: =(L26-M26)/M26 -> -0.011152733 | P26: 1'Janeiro'26 | Q26: 0.059883 | R26: 242650.63 | S26: 88812.1 | T26: =(R26-S26)/S26 -> 1.7321798 | U26: 0.010154 | V26: 6220.37 | W26: 6845.5 | X26: =(V26-W26)/W26 -> -0.091319845 | Y26: 0.009005 | Z26: 2862.1 | AA26: 4361.55 | AB26: =(Z26-AA26)/AA26 -> -0.34378833 | AC26: 0.00493 | AD26: 1.0357 | AE26: 1.1746 | AF26: =(AD26-AE26)/AE26 -> -0.11825302
A27: 2026 | B27: 1'Abril'26 | E27: =(C27-D27)/D27 -> #DIV/0! | H27: =(F27-G27)/G27 -> #DIV/0! | K27: =(I27-J27)/J27 -> #DIV/0! | N27: =(L27-M27)/M27 -> #DIV/0! | O27: 2026 | P27: 1'Abril'26 | Q27: μ = | T27: =(R27-S27)/S27 -> #DIV/0! | U27: μ = | X27: =(V27-W27)/W27 -> #DIV/0! | Y27: μ = | AB27: =(Z27-AA27)/AA27 -> #DIV/0! | AC27: μ = | AF27: =(AD27-AE27)/AE27 -> #DIV/0!
B28: 1'Julho'26 | E28: =(C28-D28)/D28 -> #DIV/0! | H28: =(F28-G28)/G28 -> #DIV/0! | K28: =(I28-J28)/J28 -> #DIV/0! | N28: =(L28-M28)/M28 -> #DIV/0! | P28: 1'Julho'26 | T28: =(R28-S28)/S28 -> #DIV/0! | X28: =(V28-W28)/W28 -> #DIV/0! | AB28: =(Z28-AA28)/AA28 -> #DIV/0! | AF28: =(AD28-AE28)/AE28 -> #DIV/0!
B29: 1'Outubro'26 | E29: =(C29-D29)/D29 -> #DIV/0! | H29: =(F29-G29)/G29 -> #DIV/0! | K29: =(I29-J29)/J29 -> #DIV/0! | N29: =(L29-M29)/M29 -> #DIV/0! | P29: 1'Outubro'26 | Q29: σ = | T29: =(R29-S29)/S29 -> #DIV/0! | U29: σ = | X29: =(V29-W29)/W29 -> #DIV/0! | Y29: σ = | AB29: =(Z29-AA29)/AA29 -> #DIV/0! | AC29: σ = | AF29: =(AD29-AE29)/AE29 -> #DIV/0!
B30: 1'Janeiro'27 | E30: =(C30-D30)/D30 -> #DIV/0! | H30: =(F30-G30)/G30 -> #DIV/0! | K30: =(I30-J30)/J30 -> #DIV/0! | N30: =(L30-M30)/M30 -> #DIV/0! | P30: 1'Janeiro'27 | T30: =(R30-S30)/S30 -> #DIV/0! | X30: =(V30-W30)/W30 -> #DIV/0! | AB30: =(Z30-AA30)/AA30 -> #DIV/0! | AF30: =(AD30-AE30)/AE30 -> #DIV/0!
D31: AVG(ABS) | E31: {=AVERAGE(ABS(E3:E26))} -> 0.15170884 | G31: AVG(ABS) | H31: {=AVERAGE(ABS(H3:H26))} -> 0.046677573 | J31: AVG(ABS) | K31: {=AVERAGE(ABS(K3:K26))} -> 0.033433764 | M31: AVG(ABS) | N31: {=AVERAGE(ABS(N3:N26))} -> 0.01567926 | S31: AVG(ABS) | T31: {=AVERAGE(ABS(T3:T26))} -> 1.0300056 | W31: AVG(ABS) | X31: {=AVERAGE(ABS(X3:X26))} -> 0.13011221 | AA31: AVG(ABS) | AB31: {=AVERAGE(ABS(AB3:AB26))} -> 0.11818649 | AE31: AVG(ABS) | AF31: {=AVERAGE(ABS(AF3:AF26))} -> 0.054849916
Q32: Bitcoin | U32: S&P 500 | Y32: Gold | AC32: EUR/USD
P33: AVG(mu) | Q33: =AVERAGE(Q4,Q8,Q12,Q16,Q20,Q24) -> 0.0029218333 | T33: AVG(mu) | U33: =AVERAGE(U4,U8,U12,U16,U20,U24) -> 0.00013083333 | X33: AVG(mu) | Y33: =AVERAGE(Y4,Y8,Y12,Y16,Y20,Y24) -> 0.00023383333 | AB33: AVG(mu) | AC33: =AVERAGE(AC4,AC8,AC12,AC16,AC20,AC24) -> 1.0333333e-05
P34: AVG(sigma) | Q34: =AVERAGE(Q6,Q10,Q14,Q18,Q22,Q26) -> 0.064662833 | T34: AVG(sigma) | U34: =AVERAGE(U6,U10,U14,U18,U22,U26) -> 0.010234333 | X34: AVG(sigma) | Y34: =AVERAGE(Y6,Y10,Y14,Y18,Y22,Y26) -> 0.0091216667 | AB34: AVG(sigma) | AC34: =AVERAGE(AC6,AC10,AC14,AC18,AC22,AC26) -> 0.0050373333
P35: Coef. variação | Q35: =Q34/Q33 -> 22.130911 | T35: Coef. variação | U35: =U34/U33 -> 78.224204 | X35: Coef. variação | Y35: =Y34/Y33 -> 39.009266 | AB35: Coef. variação | AC35: =AC34/AC33 -> 487.48387

Sheet ARIMA FINAL
A1: Monthly Model | C1: Bitcoin | G1: S&P 500 | K1: Gold | O1: EUR/USD | S1: Static Model | U1: Bitcoin | AA1: S&P 500 | AG1: Gold | AM1: EUR/USD | AU1: Estrutura
A2: Ano previsto | C2: Ordem | D2: Forecast | E2: Real | F2: Erro | G2: Ordem | H2: Forecast | I2: Real | J2: Erro | K2: Ordem | L2: Forecast | M2: Real | N2: Erro | O2: Ordem | P2: Forecast | Q2: Real | R2: Erro | S2: Ano previsto | U2: Ordem | V2: Parâmetros | X2: Forecast | Y2: Real | Z2: Erro | AA2: Ordem | AB2: Parâmetros | AD2: Forecast | AE2: Real | AF2: Erro | AG2: Ordem | AH2: Parâmetros | AJ2: Forecast | AK2: Real | AL2: Erro | AM2: Ordem | AN2: Parâmetros | AP2: Forecast | AQ2: Real | AR2: Erro | AU2: Parâmetros
A3: 2020 | B3: 1'Abril'20 | C3: (3,0,2) | D3: 9391.84 | E3: 6638.5 | F3: =(D3-E3)/E3 -> 0.41475333 | G3: (1,0,0) | H3: 2963.33 | I3: 2470.5 | J3: =(H3-I3)/I3 -> 0.19948593 | K3: (1,0,0) | L3: 1578.39 | M3: 1584.1 | N3: =(L3-M3)/M3 -> -0.0036045704 | O3: (1,0,0) | P3: 1.1028 | Q3: 1.0962 | R3: =(P3-Q3)/Q3 -> 0.0060207991 | S3: 2020 | T3: 1'Abril'20 | U3: (3,0,2) | V3: 0.836414 | W3: -0.846145 | X3: 9730.02 | Y3: 6638.5 | Z3: =(X3-Y3)/Y3 -> 0.46569556 | AA3: (1,0,0) | AB3: -0.080033 | AC3: 0 | AD3: 3262.74 | AE3: 2470.5 | AF3: =(AD3-AE3)/AE3 -> 0.32068002 | AG3: (1,0,0) | AH3: -0.014594 | AI3: 0 | AJ3: 1555.7 | AK3: 1584.1 | AL3: =(AJ3-AK3)/AK3 -> -0.017928161 | AM3: (1,0,0) | AN3: -0.016072 | AO3: 0 | AP3: 1.1222 | AQ3: 1.0962 | AR3: =(AP3-AQ3)/AQ3 -> 0.0237183 | AU3: AR1: | AV3: MA1:
B4: 1'Julho'20 | D4: 11290.93 | E4: 9229.9 | F4: =(D4-E4)/E4 -> 0.22329928 | H4: 3066.07 | I4: 3115.9 | J4: =(H4-I4)/I4 -> -0.015992169 | L4: 1756.52 | M4: 1779.9 | N4: =(L4-M4)/M4 -> -0.013135569 | P4: 1.1138 | Q4: 1.125 | R4: =(P4-Q4)/Q4 -> -0.0099555556 | T4: 1'Julho'20 | V4: -0.587543 | W4: 0.422473 | X4: 13061.99 | Y4: 9229.9 | Z4: =(X4-Y4)/Y4 -> 0.41518218 | AB4: 0 | AC4: 0 | AD4: 3295.34 | AE4: 3115.9 | AF4: =(AD4-AE4)/AE4 -> 0.057588498 | AH4: 0 | AI4: 0 | AJ4: 1588.63 | AK4: 1779.9 | AL4: =(AJ4-AK4)/AK4 -> -0.10746109 | AN4: 0 | AO4: 0 | AP4: 1.1234 | AQ4: 1.125 | AR4: =(AP4-AQ4)/AQ4 -> -0.0014222222 | AU4: AR2: | AV4: MA2:
B5: 1'Outubro'20 | D5: 13131.78 | E5: 10620.5 | F5: =(D5-E5)/E5 -> 0.23645591 | H5: 3541.19 | I5: 3380.8 | J5: =(H5-I5)/I5 -> 0.047441434 | L5: 1986.62 | M5: 1912.3 | N5: =(L5-M5)/M5 -> 0.038864195 | P5: 1.1917 | Q5: 1.1747 | R5: =(P5-Q5)/Q5 -> 0.01447178 | T5: 1'Outubro'20 | V5: 0.145298 | W5: 0 | X5: 17591.79 | Y5: 10620.5 | Z5: =(X5-Y5)/Y5 -> 0.65639942 | AB5: 0 | AC5: 0 | AD5: 3328.62 | AE5: 3380.8 | AF5: =(AD5-AE5)/AE5 -> -0.015434217 | AH5: 0 | AI5: 0 | AJ5: 1622.64 | AK5: 1912.3 | AL5: =(AJ5-AK5)/AK5 -> -0.15147205 | AN5: 0 | AO5: 0 | AP5: 1.1247 | AQ5: 1.1747 | AR5: =(AP5-AQ5)/AQ5 -> -0.042564059 | AU5: AR3: | AV5: MA3:
B6: 1'Janeiro'21 | D6: 20641.35 | E6: 29359.9 | F6: =(D6-E6)/E6 -> -0.29695435 | H6: 3678.92 | I6: 3756.1 | J6: =(H6-I6)/I6 -> -0.020547909 | L6: 1830.74 | M6: 1895.1 | N6: =(L6-M6)/M6 -> -0.033961269 | P6: 1.2078 | Q6: 1.2213 | R6: =(P6-Q6)/Q6 -> -0.011053795 | T6: 1'Janeiro'21 | V6: 0.003236 | W6: 0.004637 | X6: 23692.5 | Y6: 29359.9 | Z6: =(X6-Y6)/Y6 -> -0.19303199 | AB6: 0.000109 | AC6: 9.7e-05 | AD6: 3362.24 | AE6: 3756.1 | AF6: =(AD6-AE6)/AE6 -> -0.10485876 | AH6: 0.00023 | AI6: 8.3e-05 | AJ6: 1657.37 | AK6: 1895.1 | AL6: =(AJ6-AK6)/AK6 -> -0.12544457 | AN6: 1.2e-05 | AO6: 2.6e-05 | AP6: 1.1259 | AQ6: 1.2213 | AR6: =(AP6-AQ6)/AQ6 -> -0.078113486 | AU6: Cte: | AV6: sigma2:
A7: 2021 | B7: 1'Abril'21 | C7: (3,0,2) | D7: 55013.8 | E7: 58718.3 | F7: =(D7-E7)/E7 -> -0.063089361 | G7: (1,0,0) | H7: 3917.18 | I7: 4019.9 | J7: =(H7-I7)/I7 -> -0.025552874 | K7: (1,0,0) | L7: 1735.9 | M7: 1727.3 | N7: =(L7-M7)/M7 -> 0.0049788688 | O7: (1,0,0) | P7: 1.2055 | Q7: 1.1775 | R7: =(P7-Q7)/Q7 -> 0.023779193 | S7: 2021 | T7: 1'Abril'21 | U7: (3,0,2) | V7: 0.831536 | W7: -0.848751 | X7: 39029.66 | Y7: 58718.3 | Z7: =(X7-Y7)/Y7 -> -0.33530671 | AA7: (1,0,0) | AB7: -0.10562 | AC7: 0 | AD7: 3796.32 | AE7: 4019.9 | AF7: =(AD7-AE7)/AE7 -> -0.055618299 | AG7: (1,0,0) | AH7: -0.012926 | AI7: 0 | AJ7: 1938.29 | AK7: 1727.3 | AL7: =(AJ7-AK7)/AK7 -> 0.12215018 | AM7: (1,0,0) | AN7: -0.012011 | AO7: 0 | AP7: 1.2239 | AQ7: 1.1775 | AR7: =(AP7-AQ7)/AQ7 -> 0.03940552
B8: 1'Julho'21 | D8: 39736.27 | E8: 33543.6 | F8: =(D8-E8)/E8 -> 0.18461555 | H8: 4218.92 | I8: 4319.9 | J8: =(H8-I8)/I8 -> -0.023375541 | L8: 1918.05 | M8: 1776.8 | N8: =(L8-M8)/M8 -> 0.079496848 | P8: 1.2219 | Q8: 1.1848 | R8: =(P8-Q8)/Q8 -> 0.031313302 | T8: 1'Julho'21 | V8: -0.597225 | W8: 0.447378 | X8: 52653.22 | Y8: 33543.6 | Z8: =(X8-Y8)/Y8 -> 0.56969496 | AB8: 0 | AC8: 0 | AD8: 3839.28 | AE8: 4319.9 | AF8: =(AD8-AE8)/AE8 -> -0.11125721 | AH8: 0 | AI8: 0 | AJ8: 1982.47 | AK8: 1776.8 | AL8: =(AJ8-AK8)/AK8 -> 0.11575304 | AN8: 0 | AO8: 0 | AP8: 1.2264 | AQ8: 1.1848 | AR8: =(AP8-AQ8)/AQ8 -> 0.035111411 | AT8: LONG RUN 2020-2025
B9: 1'Outubro'21 | D9: 54077.78 | E9: 48146 | F9: =(D9-E9)/E9 -> 0.123204 | H9: 4543.91 | I9: 4357 | J9: =(H9-I9)/I9 -> 0.042898784 | L9: 1826.88 | M9: 1757.7 | N9: =(L9-M9)/M9 -> 0.039358252 | P9: 1.1844 | Q9: 1.1594 | R9: =(P9-Q9)/Q9 -> 0.021562877 | T9: 1'Outubro'21 | V9: 0.133311 | W9: 0 | X9: 71266.28 | Y9: 48146 | Z9: =(X9-Y9)/Y9 -> 0.48021186 | AB9: 0 | AC9: 0 | AD9: 3883.21 | AE9: 4357 | AF9: =(AD9-AE9)/AE9 -> -0.10874225 | AH9: 0 | AI9: 0 | AJ9: 2028.17 | AK9: 1757.7 | AL9: =(AJ9-AK9)/AK9 -> 0.15387723 | AN9: 0 | AO9: 0 | AP9: 1.229 | AQ9: 1.1594 | AR9: =(AP9-AQ9)/AQ9 -> 0.060031051 | AT9: ASSET | AU9: Bitcoin | AV9: S&P 500 | AW9: Gold | AX9: EUR/USD
B10: 1'Janeiro'22 | D10: 63506.04 | E10: 47738 | F10: =(D10-E10)/E10 -> 0.33030374 | H10: 4540.73 | I10: 4766.2 | J10: =(H10-I10)/I10 -> -0.04730603 | L10: 1796.12 | M10: 1828.6 | N10: =(L10-M10)/M10 -> -0.017762222 | P10: 1.1323 | Q10: 1.1368 | R10: =(P10-Q10)/Q10 -> -0.0039584799 | T10: 1'Janeiro'22 | V10: 0.00329 | W10: 0.004369 | X10: 96459.09 | Y10: 47738 | Z10: =(X10-Y10)/Y10 -> 1.0205934 | AB10: 0.000124 | AC10: 0.000107 | AD10: 3927.64 | AE10: 4766.2 | AF10: =(AD10-AE10)/AE10 -> -0.1759389 | AH10: 0.000248 | AI10: 8.5e-05 | AJ10: 2074.92 | AK10: 1828.6 | AL10: =(AJ10-AK10)/AK10 -> 0.13470415 | AN10: 2.3e-05 | AO10: 2.6e-05 | AP10: 1.2316 | AQ10: 1.1368 | AR10: =(AP10-AQ10)/AQ10 -> 0.083391977 | AT10: Jan 1st, 2026 | AU10: 88812.1 | AV10: 6845.5 | AW10: 4361.55 | AX10: 1.1746
